<?xml version="1.0" encoding="UTF-8"?>
<!-- Generated by org.testng.reporters.JUnitReportReporter -->
<testsuite hostname="vnvpc130" name="TestCases.LoginVerification" tests="1" failures="1" timestamp="30 Apr 2012 14:50:04 GMT" time="17415.809" errors="0">
  <testcase name="userLogin" time="17415.809" classname="TestCases.LoginVerification">
    <failure type="com.thoughtworks.selenium.SeleniumException" message="Connection refused: connect">
      <![CDATA[com.thoughtworks.selenium.SeleniumException: Connection refused: connect
	at com.thoughtworks.selenium.HttpCommandProcessor.executeCommandOnServlet(HttpCommandProcessor.java:121)
	at com.thoughtworks.selenium.HttpCommandProcessor.doCommand(HttpCommandProcessor.java:101)
	at com.thoughtworks.selenium.DefaultSelenium.waitForPageToLoad(DefaultSelenium.java:671)
	at TestCases.LoginVerification.userLogin(LoginVerification.java:29)
	at sun.reflect.NativeMethodAccessorImpl.invoke0(Native Method)
	at sun.reflect.NativeMethodAccessorImpl.invoke(Unknown Source)
	at sun.reflect.DelegatingMethodAccessorImpl.invoke(Unknown Source)
	at java.lang.reflect.Method.invoke(Unknown Source)
	at org.testng.internal.MethodInvocationHelper.invokeMethod(MethodInvocationHelper.java:76)
	at org.testng.internal.Invoker.invokeMethod(Invoker.java:673)
	at org.testng.internal.Invoker.invokeTestMethod(Invoker.java:846)
	at org.testng.internal.Invoker.invokeTestMethods(Invoker.java:1170)
	at org.testng.internal.TestMethodWorker.invokeTestMethods(TestMethodWorker.java:125)
	at org.testng.internal.TestMethodWorker.run(TestMethodWorker.java:109)
	at org.testng.TestRunner.runWorkers(TestRunner.java:1147)
	at org.testng.TestRunner.privateRun(TestRunner.java:749)
	at org.testng.TestRunner.run(TestRunner.java:600)
	at org.testng.SuiteRunner.runTest(SuiteRunner.java:317)
	at org.testng.SuiteRunner.runSequentially(SuiteRunner.java:312)
	at org.testng.SuiteRunner.privateRun(SuiteRunner.java:274)
	at org.testng.SuiteRunner.run(SuiteRunner.java:223)
	at org.testng.SuiteRunnerWorker.runSuite(SuiteRunnerWorker.java:52)
	at org.testng.SuiteRunnerWorker.run(SuiteRunnerWorker.java:86)
	at org.testng.TestNG.runSuitesSequentially(TestNG.java:1039)
	at org.testng.TestNG.runSuitesLocally(TestNG.java:964)
	at org.testng.TestNG.run(TestNG.java:900)
	at org.testng.TestNG.privateMain(TestNG.java:1182)
	at org.testng.TestNG.main(TestNG.java:1146)
Caused by: java.net.ConnectException: Connection refused: connect
	at java.net.TwoStacksPlainSocketImpl.socketConnect(Native Method)
	at java.net.AbstractPlainSocketImpl.doConnect(Unknown Source)
	at java.net.AbstractPlainSocketImpl.connectToAddress(Unknown Source)
	at java.net.AbstractPlainSocketImpl.connect(Unknown Source)
	at java.net.PlainSocketImpl.connect(Unknown Source)
	at java.net.SocksSocketImpl.connect(Unknown Source)
	at java.net.Socket.connect(Unknown Source)
	at java.net.Socket.connect(Unknown Source)
	at sun.net.NetworkClient.doConnect(Unknown Source)
	at sun.net.www.http.HttpClient.openServer(Unknown Source)
	at sun.net.www.http.HttpClient.openServer(Unknown Source)
	at sun.net.www.http.HttpClient.parseHTTPHeader(Unknown Source)
	at sun.net.www.http.HttpClient.parseHTTP(Unknown Source)
	at sun.net.www.protocol.http.HttpURLConnection.getInputStream(Unknown Source)
	at java.net.HttpURLConnection.getResponseCode(Unknown Source)
	at com.thoughtworks.selenium.HttpCommandProcessor.getResponseCode(HttpCommandProcessor.java:159)
	at com.thoughtworks.selenium.HttpCommandProcessor.getCommandResponseAsString(HttpCommandProcessor.java:179)
	at com.thoughtworks.selenium.HttpCommandProcessor.executeCommandOnServlet(HttpCommandProcessor.java:118)
	... 27 more
]]>
    </failure>
  </testcase>
</testsuite>
